Workbook

Sheet Power
A1: MAE 161C — SATELLITE CHASERS | EPS SIZING
A2: SECTION 0 — Inputs
A3: 0.1 Orbital inputs
A4: Parameter | B4: Value | C4: Unit | D4: Formula / Notes | E4: Source
A5: Earth radius Re | B5: 6371 | C5: km
A6: Gravitational param μ | B6: 398600 | C6: km³/s²
A7: Orbit altitude h | B7: 550 | C7: km | D7: Defined by the mission trajectory subsystem
A8: Beta angle β (worst case) | B8: 0 | C8: deg | D8: β = 0° gives maximum eclipse duration (worst case scenario)
A9: Mission lifetime | B9: 5 | C9: yr | D9: Project requirements - note: Expected mission duration is ~1 year, but project requirements set a 5-year design life; therefore, the power system is sized accordingly.
A10: Solar irradiance | B10: 1360 | C10: W/m² | D10: Solar constant at 1 AU. Standard physical value.
A11: 0.2 Solar array inputs — Selected cell: Azur Space 3G30C-Advanced
A12: Parameter | B12: Value | C12: Unit | D12: Formula / Notes | E12: Source / Link
A13: Cell efficiency BOL | B13: 0.295 | C13: — | D13: BOL efficiency taken directly from Azur Space 3G30C-Advanced datasheet on table Typical Electrical Performance, row η (1367 W/m²), column BOL Cell: 29.5%. | E13: 30% Triple-Junction (TJ) - III-V Bare Solar Cells & Assemblies
A14: Packing factor | B14: 0.9 | C14: — | D14: Fraction of panel area covered by solar cells. Using 90% as used by NASA | E14: Spacecraft Electrical Power Systems
A15: Cell EOL efficiency factor (1 yr, 550 km LEO) | B15: 0.919 | C15: — | D15: EOL efficiency factor taken directly from Azur Space 3G30C-Advanced datasheet table 'Typical Electrical Performance', row η (1367 W/m²). We use fluence column 1×10¹⁵ e⁻/cm² (1 MeV electrons) as a conservative design choice; this is the highest fluence column in the datasheet applicable to LEO missions, giving the lowest EOL efficiency and therefore the largest required array area. η = 27.1% (Cell) → EOL factor = 27.1 / 29.5 = 0.919." | E15: 30% Triple-Junction (TJ) - III-V Bare Solar Cells & Assemblies
A16: Sunlight path eff. Xe | B16: 0.85 | C16: — | D16: Estimate: Efficiency of the sunlight power path (solar array output → PCDU → load). Accounts for losses between array and load. Value 0.85 is the upper end of the typical range for LEO deployable GaAs arrays. | E16: Spacecraft Electrical Power Systems
A17: Eclipse path eff. Xd | B17: 0.96 | C17: — | D17: Efficiency of the eclipse power path (battery → PCDU → load). Set equal to PCDU conversion efficiency (96%, S3R topology). Battery discharge losses assumed covered by the 15% battery safety margin applied | E17: Approximation
A18: Number of wings | B18: 2 | C18: —
A19: 0.3 Battery & PCDU inputs — Selected: Saft VES16 (battery) + Terma PCDU (S3R, 96% eff.)
A20: Parameter | B20: Value | C20: Unit | D20: Formula / Notes | E20: Source
A21: Max depth of discharge | B21: 0.7 | C21: — | D21: The Depth of Discharge (DoD) for LEO operation is assumed to be 30%, based on a Saft VES16 presentation, which states that LEO satellite batteries are typically designed for 20–40% DoD. 30% is used as a conservative value. This means the battery can discharge down to 30%. | E21: VES16 Batteries for LEO and GEO Satellites Dr. Y.Borthomieu, Dr. V.Armel B. Le Guern
A22: Battery EOL capacity factor (1 yr, 30% DoD) | B22: 0.95 | C22: — | D22: Estimation: EOL capacity factor for the battery after 5 years at 30% DoD. Saft VES16 SPW 2019 slide 9 shows measured real-time cycling data: '12% energy loss for 12 years LEO mission at 30% DoD'. We can do an interpolation for 5 years: assuming linear fade → 12% × (5/12) = 5% loss → factor = 0.95. Linear interpolarion should be a good enough estimate. | E22: VES16 Batteries for LEO and GEO Satellites Dr. Y.Borthomieu, Dr. V.Armel B. Le Guern
A23: Battery safety margin | B23: 0.15 | C23: — | D23: 15% safety margin added on top of the EOL-sized battery capacity.
A24: Li-ion energy density | B24: 155 | C24: Wh/kg | D24: Minimum specific energy taken directly from Saft VES16 SPW 2019, slide 3 ('VES16 cell main features' table): 'Specific energy > 155 Wh/kg'. | E24: VES16 Batteries for LEO and GEO Satellites Dr. Y.Borthomieu, Dr. V.Armel B. Le Guern
A25: PCDU efficiency | B25: 0.96 | C25: — | D25: The S3R used in the Terma PCDU has an estimated efficiency of about 96%, based on a 2021 MDPI Energies paper. Terma does not publish an exact efficiency value, but since their PCDU uses the same S3R architecture, we use 96% as its reasonable. | E25: Power Bus Management Techniques for Space Missions in Low Earth Orbit -- 'Thus, efficiency can be larger than 96%, depending on the bus voltage.'
A27: SECTION 1 — Power demands
A28: 1.1 Mode totals
A29: Parameter | B29: Value | C29: Unit | D29: Formula / Notes | E29: Source
A30: Thrusting (solar array driver ←) | B30: =PEL!T40*1.3-PEL!O37*1.3 -> 3462.992 | C30: W | D30: (MEV of mode - PCDU losses)*1.3 | E30: Cross-reference to PEL sheet. PCDU losses subtracted: already accounted for in the SMAD sizing via Xe/Xd. Counting them as a load too would double-count.
A31: Eclipse (battery driver ←) | B31: =PEL!W40*1.3-PEL!O37*1.3 -> 1236.2958 | C31: W | D31: (MEV of mode - PCDU losses)*1.3 | E31: Cross-reference to PEL sheet. PCDU losses subtracted: already accounted for in the SMAD sizing via Xe/Xd. Counting them as a load too would double-count.
A32: Rendezvous | B32: =PEL!U40*1.3-PEL!O37*1.3 -> 1339.442 | C32: W | D32: (MEV of mode - PCDU losses)*1.3 | E32: Cross-reference to PEL sheet. PCDU losses subtracted: already accounted for in the SMAD sizing via Xe/Xd. Counting them as a load too would double-count.
A33: Imaging | B33: =PEL!R40*1.3-PEL!O37*1.3 -> 1385.774 | C33: W | D33: (MEV of mode - PCDU losses)*1.3 | E33: Cross-reference to PEL sheet. PCDU losses subtracted: already accounted for in the SMAD sizing via Xe/Xd. Counting them as a load too would double-count.
A34: Refueling | B34: =PEL!S40*1.3-PEL!O37*1.3 -> 1453.192 | C34: W | D34: (MEV of mode - PCDU losses)*1.3 | E34: Cross-reference to PEL sheet. PCDU losses subtracted: already accounted for in the SMAD sizing via Xe/Xd. Counting them as a load too would double-count.
A35: Nominal | B35: =PEL!Q40*1.3-PEL!O37*1.3 -> 415.519 | C35: W | D35: (MEV of mode - PCDU losses)*1.3 | E35: Cross-reference to PEL sheet. PCDU losses subtracted: already accounted for in the SMAD sizing via Xe/Xd. Counting them as a load too would double-count.
A36: Downlink | B36: =PEL!V40*1.3-PEL!O37*1.3 -> 415.662 | C36: W | D36: (MEV of mode - PCDU losses)*1.3 | E36: Cross-reference to PEL sheet. PCDU losses subtracted: already accounted for in the SMAD sizing via Xe/Xd. Counting them as a load too would double-count.
A37: Standby | B37: =PEL!P40*1.3-PEL!O37*1.3 -> 365.911 | C37: W | D37: (MEV of mode - PCDU losses)*1.3 | E37: Cross-reference to PEL sheet. PCDU losses subtracted: already accounted for in the SMAD sizing via Xe/Xd. Counting them as a load too would double-count.
A38: Safe mode | B38: =PEL!X40*1.3-PEL!O37*1.3 -> 344.461 | C38: W | D38: (MEV of mode - PCDU losses)*1.3 | E38: Cross-reference to PEL sheet. PCDU losses subtracted: already accounted for in the SMAD sizing via Xe/Xd. Counting them as a load too would double-count.
A40: SECTION 2 — Orbital mechanics & eclipse
A41: 2.1 Orbital period — T = 2π × SQRT(r³ / μ)
A42: Parameter | B42: Value | C42: Unit | D42: Formula / Notes | E42: Source
...

Sheet PEL
A1: MAE 161C — SATELLITE CHASERS | POWER EQUIPMENT LIST (PEL) | Electrical Power System (EPS) | K1: SECTION 2 — Operational Modes Power Matrix | 0 = OFF | 1 = ON | Total rows use Excel formulas (change any 0/1 and totals update automatically)
A2: SECTION 1 — Component Power List with Contingency and Maximum Estimated Value (MEV) | K2: Subsystem | L2: Component | M2: CBE (W) | N2: Cont. (%) | O2: MEV (W) | P2: Standby | Q2: Nominal | R2: Imaging | S2: Refueling | T2: Thrusting | U2: Rendezvous (Proximity) | V2: Downlink | W2: Eclipse | X2: Safe Mode | Y2: Notes
A3: Subsystem | B3: Component | C3: Operating Mode | D3: CBE (W) Current Best Estimate | E3: Contingency (%) | F3: MEV (W) Max Estimated Value | G3: Source | H3: Notes | K3: Payload 1 – Imaging
A4: Payload 1 – Imaging | L4: Mast-Z Camera | M4: =D5 -> 17.4 | N4: =E5 -> 0.1 | O4: =F5 -> 19.14 | P4: 0 | Q4: 0 | R4: 1 | S4: 0 | T4: 0 | U4: 0 | V4: 0 | W4: 0 | X4: 0 | Y4: Active only during imaging.
A5: Payload 1 – Imaging | B5: Mast-Z Camera | C5: Imaging mode | D5: 17.4 | E5: 0.1 | F5: =D5*(1+E5) -> 19.14 | G5: Design Worksheet – Imaging sheet | L5: Mast-Z Camera (Standby) | M5: =D6 -> 2 | N5: =E6 -> 0.1 | O5: =F6 -> 2.2 | P5: 1 | Q5: 1 | R5: 0 | S5: 1 | T5: 1 | U5: 1 | V5: 1 | W5: 1 | X5: 0 | Y5: Active all modes except imaging and safe.
A6: Payload 1 – Imaging | B6: Mast-Z Camera (Standby) | C6: Standby mode | D6: 2 | E6: 0.1 | F6: =D6*(1+E6) -> 2.2 | G6: Estimate | L6: Innoflight CFC-400 Flight Computer | M6: =D7 -> 20 | N6: =E7 -> 0.1 | O6: =F7 -> 22 | P6: 0 | Q6: 0 | R6: 1 | S6: 0 | T6: 0 | U6: 0 | V6: 0 | W6: 0 | X6: 0 | Y6: Active only during imaging.
A7: Payload 1 – Imaging | B7: Innoflight CFC-400 Flight Computer | C7: Imaging mode | D7: 20 | E7: 0.1 | F7: =D7*(1+E7) -> 22 | G7: Design Worksheet – Imaging sheet | L7: CFC-400 Flight Computer (Standby) | M7: =D8 -> 3 | N7: =E8 -> 0.1 | O7: =F8 -> 3.3 | P7: 1 | Q7: 1 | R7: 0 | S7: 1 | T7: 1 | U7: 1 | V7: 1 | W7: 1 | X7: 0 | Y7: Active all modes except imaging and safe.
A8: Payload 1 – Imaging | B8: CFC-400 Flight Computer (Standby) | C8: Standby mode | D8: 3 | E8: 0.1 | F8: =D8*(1+E8) -> 3.3 | G8: Estimate | K8: Payload 2 – Refueling
A9: Payload 2 – Refueling | L9: Propellant Line Heaters | M9: =D10 -> 30 | N9: =E10 -> 0.1 | O9: =F10 -> 33 | P9: 0 | Q9: 0 | R9: 0 | S9: 1 | T9: 0 | U9: 0 | V9: 0 | W9: 0 | X9: 0 | Y9: Active only during refueling.
A10: Payload 2 – Refueling | B10: Propellant Line Heaters | C10: Refueling mode | D10: 30 | E10: 0.1 | F10: =D10*(1+E10) -> 33 | G10: Design Worksheet – Refueling sheet Sec. 6 | L10: Valve Actuators | M10: =D11 -> 20 | N10: =E11 -> 0.1 | O10: =F11 -> 22 | P10: 0 | Q10: 0 | R10: 0 | S10: 1 | T10: 0 | U10: 0 | V10: 0 | W10: 0 | X10: 0 | Y10: Active only during refueling.
A11: Payload 2 – Refueling | B11: Valve Actuators | C11: Refueling mode | D11: 20 | E11: 0.1 | F11: =D11*(1+E11) -> 22 | G11: Design Worksheet – Refueling sheet Sec. 6 | L11: Flow and Pressure Sensors | M11: =D12 -> 10 | N11: =E12 -> 0.1 | O11: =F12 -> 11 | P11: 0 | Q11: 0 | R11: 0 | S11: 1 | T11: 0 | U11: 0 | V11: 0 | W11: 0 | X11: 0 | Y11: Active only during refueling.
A12: Payload 2 – Refueling | B12: Flow and Pressure Sensors | C12: Refueling mode | D12: 10 | E12: 0.1 | F12: =D12*(1+E12) -> 11 | G12: Design Worksheet – Refueling sheet Sec. 6 | L12: Control Electronics Board | M12: =D13 -> 25 | N12: =E13 -> 0.3 | O12: =F13 -> 32.5 | P12: 0 | Q12: 0 | R12: 0 | S12: 1 | T12: 0 | U12: 0 | V12: 0 | W12: 0 | X12: 0 | Y12: Active only during refueling.
A13: Payload 2 – Refueling | B13: Control Electronics Board | C13: Refueling mode | D13: 25 | E13: 0.3 | F13: =D13*(1+E13) -> 32.5 | G13: Design Worksheet – Refueling sheet Sec. 6 | L13: Refueling System (Standby) | M13: =D14 -> 10 | N13: =E14 -> 0.1 | O13: =F14 -> 11 | P13: 1 | Q13: 1 | R13: 1 | S13: 0 | T13: 1 | U13: 1 | V13: 1 | W13: 1 | X13: 0 | Y13: Active all modes except refueling and safe.
A14: Payload 2 – Refueling | B14: Refueling System (Standby) | C14: Standby mode | D14: 10 | E14: 0.1 | F14: =D14*(1+E14) -> 11 | G14: Design Worksheet – Refueling sheet Sec. 6 | K14: Propulsion
A15: Propulsion | L15: SPT-100 Hall Thruster | M15: =D16 -> 1350 | N15: =E16 -> 0.1 | O15: =F16 -> 1485 | P15: 0 | Q15: 0 | R15: 0 | S15: 0 | T15: 1 | U15: 0 | V15: 0 | W15: 0 | X15: 0 | Y15: Active only during Hall thrusting.
A16: Propulsion | B16: SPT-100 Hall Thruster | C16: Thrusting mode | D16: 1350 | E16: 0.1 | F16: =D16*(1+E16) -> 1485 | G16: Design Worksheet – Propulsion / Trajectory | L16: Power Processing Unit (PPU) | M16: =D17 -> 135 | N16: =E17 -> 0.1 | O16: =F17 -> 148.5 | P16: 0 | Q16: 0 | R16: 0 | S16: 0 | T16: 1 | U16: 0 | V16: 0 | W16: 0 | X16: 0 | Y16: Active only with SPT-100.
A17: Propulsion | B17: Power Processing Unit (PPU) | C17: Thrusting mode | D17: =0.1*D16 -> 135 | E17: 0.1 | F17: =D17*(1+E17) -> 148.5 | G17: Estimate | H17: Estimated around 10% losses of SPT-100 | K17: Attitude Determination and Control System (ADCS)
A18: Attitude Determination and Control System (ADCS) | L18: Reaction Wheel Motors ×4 | M18: =D19 -> 213.7 | N18: =E19 -> 0.1 | O18: =F19 -> 235.07 | P18: 1 | Q18: 1 | R18: 1 | S18: 1 | T18: 1 | U18: 1 | V18: 1 | W18: 1 | X18: 1 | Y18: Active in all modes — attitude always required.
A19: ADCS | B19: Reaction Wheel Motors ×4 | C19: Nominal mode | D19: 213.7 | E19: 0.1 | F19: =D19*(1+E19) -> 235.07 | G19: ACS Worksheet – Electrical System sheet | L19: RCS Solenoid Valves ×36 | M19: =D20 -> 144 | N19: =E20 -> 0.1 | O19: =F20 -> 158.4 | P19: 0 | Q19: 0 | R19: 1 | S19: 1 | T19: 1 | U19: 1 | V19: 0 | W19: 0 | X19: 0 | Y19: RCS active during imaging, refueling, thrusting, rendezvous.
A20: ADCS | B20: RCS Solenoid Valves ×36 | C20: RCS mode | D20: 144 | E20: 0.1 | F20: =D20*(1+E20) -> 158.4 | G20: ACS Worksheet – Fluid System sheet | L20: RCS Flow Meters ×24 | M20: =D21 -> 96 | N20: =E21 -> 0.1 | O20: =F21 -> 105.6 | P20: 0 | Q20: 0 | R20: 1 | S20: 1 | T20: 1 | U20: 1 | V20: 0 | W20: 0 | X20: 0 | Y20: RCS active during imaging, refueling, thrusting, rendezvous.
A21: ADCS | B21: RCS Flow Meters ×24 | C21: RCS mode | D21: 96 | E21: 0.1 | F21: =D21*(1+E21) -> 105.6 | G21: ACS Worksheet – Fluid System sheet | L21: RCS Pumps ×12 | M21: =D22 -> 406.1 | N21: =E22 -> 0.1 | O21: =F22 -> 446.71 | P21: 0 | Q21: 0 | R21: 1 | S21: 1 | T21: 1 | U21: 1 | V21: 0 | W21: 0 | X21: 0 | Y21: RCS active during imaging, refueling, thrusting, rendezvous.
A22: ADCS | B22: RCS Pumps ×12 | C22: RCS mode | D22: 406.1 | E22: 0.1 | F22: =D22*(1+E22) -> 446.71 | G22: ACS Worksheet – Fluid System sheet | L22: Gyroscopes ×4 | M22: =D23 -> 10 | N22: =E23 -> 0.1 | O22: =F23 -> 11 | P22: 1 | Q22: 1 | R22: 1 | S22: 1 | T22: 1 | U22: 1 | V22: 1 | W22: 1 | X22: 1 | Y22: Active in all modes.
A23: ADCS | B23: Gyroscopes ×4 | C23: Nominal mode | D23: 10 | E23: 0.1 | F23: =D23*(1+E23) -> 11 | G23: Estimate | L23: Star Trackers ×12 | M23: =D24 -> 24 | N23: =E24 -> 0.1 | O23: =F24 -> 26.4 | P23: 0 | Q23: 1 | R23: 1 | S23: 1 | T23: 1 | U23: 1 | V23: 1 | W23: 0 | X23: 0 | Y23: Off during eclipse, safe, and standby.
A24: ADCS | B24: Star Trackers ×12 | C24: Nominal mode | D24: 24 | E24: 0.1 | F24: =D24*(1+E24) -> 26.4 | G24: Estimate | L24: Sun Sensors ×12 | M24: =D25 -> 6 | N24: =E25 -> 0.1 | O24: =F25 -> 6.6 | P24: 0 | Q24: 1 | R24: 1 | S24: 1 | T24: 1 | U24: 1 | V24: 1 | W24: 0 | X24: 0 | Y24: Off during eclipse, safe, and standby.
A25: ADCS | B25: Sun Sensors ×12 | C25: Nominal mode | D25: 6 | E25: 0.1 | F25: =D25*(1+E25) -> 6.6 | G25: Estimate | L25: Magnetometers ×4 | M25: =D26 -> 2 | N25: =E26 -> 0.1 | O25: =F26 -> 2.2 | P25: 1 | Q25: 1 | R25: 1 | S25: 1 | T25: 1 | U25: 1 | V25: 1 | W25: 1 | X25: 1 | Y25: Active in all modes — low power, always on.
A26: ADCS | B26: Magnetometers ×4 | C26: Nominal mode | D26: 2 | E26: 0.1 | F26: =D26*(1+E26) -> 2.2 | G26: Estimate | K26: Telecommunications (Telecom)
A27: Telecommunications (Telecom) | L27: Innoflight SCR-106 X-band Transmitter | M27: =D28 -> 0.1 | N27: =E28 -> 0.1 | O27: =F28 -> 0.11 | P27: 0 | Q27: 0 | R27: 0 | S27: 0 | T27: 0 | U27: 0 | V27: 1 | W27: 0 | X27: 0 | Y27: Active only during downlink.
A28: Telecom | B28: Innoflight SCR-106 X-band Transmitter | C28: Downlink mode | D28: 0.1 | E28: 0.1 | F28: =D28*(1+E28) -> 0.11 | G28: TelecomCDH sheet | L28: EnduroSat X-band Patch Antenna | M28: =D29 -> 0 | N28: =E29 -> 0.1 | O28: =F29 -> 0 | P28: 0 | Q28: 0 | R28: 0 | S28: 0 | T28: 0 | U28: 0 | V28: 1 | W28: 0 | X28: 0 | Y28: Active with transmitter.
A29: Telecom | B29: EnduroSat X-band Patch Antenna | C29: Downlink mode | D29: 0 | E29: 0.1 | F29: =D29*(1+E29) -> 0 | G29: TelecomCDH sheet | L29: TT&C Receiver (S-band uplink) | M29: =D30 -> 3 | N29: =E30 -> 0.1 | O29: =F30 -> 3.3 | P29: 1 | Q29: 1 | R29: 1 | S29: 1 | T29: 1 | U29: 1 | V29: 1 | W29: 1 | X29: 1 | Y29: Always active — commands must be receivable at any time.
A30: Telecom | B30: TT&C Receiver (S-band uplink) | C30: All modes | D30: 3 | E30: 0.1 | F30: =D30*(1+E30) -> 3.3 | G30: TelecomCDH sheet | K30: Command and Data Handling (C&DH)
A31: Command and Data Handling (C&DH) | L31: Flight Computer – Nominal | M31: =D32 -> 6.3 | N31: =E32 -> 0.2 | O31: =F32 -> 7.56 | P31: 0 | Q31: 1 | R31: 1 | S31: 1 | T31: 1 | U31: 1 | V31: 1 | W31: 1 | X31: 0 | Y31: Always active in normal conditions
A32: C&DH | B32: Flight Computer – Nominal | C32: Nominal mode | D32: 6.3 | E32: 0.2 | F32: =D32*(1+E32) -> 7.56 | G32: TelecomCDH sheet | L32: Flight Computer – Safe/Standby | M32: =D33 -> 2 | N32: =E33 -> 0.2 | O32: =F33 -> 2.4 | P32: 1 | Q32: 0 | R32: 0 | S32: 0 | T32: 0 | U32: 0 | V32: 0 | W32: 0 | X32: 1 | Y32: 2 W only in standby and safe mode.
A33: C&DH | B33: Flight Computer – Safe/Standby | C33: Safe/Standby mode | D33: 2 | E33: 0.2 | F33: =D33*(1+E33) -> 2.4 | G33: Estimate | K33: Thermal Control System
A34: Thermal Control System | L34: Survival Heaters – Eclipse | M34: =D35 -> 511.05138 | N34: =E35 -> 0.3 | O34: =F35 -> 664.36679 | P34: 0 | Q34: 0 | R34: 0 | S34: 0 | T34: 0 | U34: 0 | V34: 0 | W34: 1 | X34: 0 | Y34: Active only during eclipse.
A35: Thermal | B35: Survival Heaters – Eclipse | C35: Eclipse mode | D35: 511.05138 | E35: 0.3 | F35: =D35*(1+E35) -> 664.36679 | G35: Design Worksheet – Thermal sheet | L35: Thermal Controllers and Sensors | M35: =D36 -> 10 | N35: =E36 -> 0.1 | O35: =F36 -> 11 | P35: 1 | Q35: 1 | R35: 1 | S35: 1 | T35: 1 | U35: 1 | V35: 1 | W35: 1 | X35: 1 | Y35: Active in all modes — continuous monitoring.
A36: Thermal | B36: Thermal Controllers and Sensors | C36: Nominal mode | D36: 10 | E36: 0.1 | F36: =D36*(1+E36) -> 11 | G36: Design Worksheet – Thermal sheet | K36: Electrical Power System (EPS)
A37: Electrical Power System (EPS) | L37: Power Control and Distribution Unit (PCDU) | M37: =D38 -> 193.5099 | N37: =E38 -> 0.1 | O37: =F38 -> 212.86089 | P37: 1 | Q37: 1 | R37: 1 | S37: 1 | T37: 1 | U37: 1 | V37: 1 | W37: 1 | X37: 1 | Y37: Active in all modes — continuous DC/DC conversion.
A38: EPS | B38: Power Control and Distribution Unit (PCDU) | C38: All modes | D38: =Power!B104 -> 193.5099 | E38: 0.1 | F38: =D38*(1+E38) -> 212.86089
K39: TOTAL CBE per Mode (W) | P39: =M4*P4+M5*P5+M6*P6+M7*P7+M9*P9+M10*P10+M11*P11+M12*P12+M13*P13+M15*P15+M16*P16+M18*P18+M19*P19+M20*P20+M21*P21+M22*P22+M23*P23+M24*P24+M25*P25+M27*P27+M28*P28+M29*P29+M31*P31+M32*P32+M34*P34+M35*P35+M37*P37 -> 449.2099 | Q39: =M4*Q4+M5*Q5+M6*Q6+M7*Q7+M9*Q9+M10*Q10+M11*Q11+M12*Q12+M13*Q13+M15*Q15+M16*Q16+M18*Q18+M19*Q19+M20*Q20+M21*Q21+M22*Q22+M23*Q23+M24*Q24+M25*Q25+M27*Q27+M28*Q28+M29*Q29+M31*Q31+M32*Q32+M34*Q34+M35*Q35+M37*Q37 -> 483.5099 | R39: =M4*R4+M5*R5+M6*R6+M7*R7+M9*R9+M10*R10+M11*R11+M12*R12+M13*R13+M15*R15+M16*R16+M18*R18+M19*R19+M20*R20+M21*R21+M22*R22+M23*R23+M24*R24+M25*R25+M27*R27+M28*R28+M29*R29+M31*R31+M32*R32+M34*R34+M35*R35+M37*R37 -> 1162.0099 | S39: =M4*S4+M5*S5+M6*S6+M7*S7+M9*S9+M10*S10+M11*S11+M12*S12+M13*S13+M15*S15+M16*S16+M18*S18+M19*S19+M20*S20+M21*S21+M22*S22+M23*S23+M24*S24+M25*S25+M27*S27+M28*S28+M29*S29+M31*S31+M32*S32+M34*S34+M35*S35+M37*S37 -> 1204.6099 | T39: =M4*T4+M5*T5+M6*T6+M7*T7+M9*T9+M10*T10+M11*T11+M12*T12+M13*T13+M15*T15+M16*T16+M18*T18+M19*T19+M20*T20+M21*T21+M22*T22+M23*T23+M24*T24+M25*T25+M27*T27+M28*T28+M29*T29+M31*T31+M32*T32+M34*T34+M35*T35+M37*T37 -> 2614.6099 | U39: =M4*U4+M5*U5+M6*U6+M7*U7+M9*U9+M10*U10+M11*U11+M12*U12+M13*U13+M15*U15+M16*U16+M18*U18+M19*U19+M20*U20+M21*U21+M22*U22+M23*U23+M24*U24+M25*U25+M27*U27+M28*U28+M29*U29+M31*U31+M32*U32+M34*U34+M35*U35+M37*U37 -> 1129.6099 | V39: =M4*V4+M5*V5+M6*V6+M7*V7+M9*V9+M10*V10+M11*V11+M12*V12+M13*V13+M15*V15+M16*V16+M18*V18+M19*V19+M20*V20+M21*V21+M22*V22+M23*V23+M24*V24+M25*V25+M27*V27+M28*V28+M29*V29+M31*V31+M32*V32+M34*V34+M35*V35+M37*V37 -> 483.6099 | W39: =M4*W4+M5*W5+M6*W6+M7*W7+M9*W9+M10*W10+M11*W11+M12*W12+M13*W13+M15*W15+M16*W16+M18*W18+M19*W19+M20*W20+M21*W21+M22*W22+M23*W23+M24*W24+M25*W25+M27*W27+M28*W28+M29*W29+M31*W31+M32*W32+M34*W34+M35*W35+M37*W37 -> 964.56128 | X39: =M4*X4+M5*X5+M6*X6+M7*X7+M9*X9+M10*X10+M11*X11+M12*X12+M13*X13+M15*X15+M16*X16+M18*X18+M19*X19+M20*X20+M21*X21+M22*X22+M23*X23+M24*X24+M25*X25+M27*X27+M28*X28+M29*X29+M31*X31+M32*X32+M34*X34+M35*X35+M37*X37 -> 434.2099 | Y39: CBE × mode flag. Update any 0/1 above and this row recalculates.
K40: TOTAL MEV per Mode (W) | P40: =O4*P4+O5*P5+O6*P6+O7*P7+O9*P9+O10*P10+O11*P11+O12*P12+O13*P13+O15*P15+O16*P16+O18*P18+O19*P19+O20*P20+O21*P21+O22*P22+O23*P23+O24*P24+O25*P25+O27*P27+O28*P28+O29*P29+O31*P31+O32*P32+O34*P34+O35*P35+O37*P37 -> 494.33089 | Q40: =O4*Q4+O5*Q5+O6*Q6+O7*Q7+O9*Q9+O10*Q10+O11*Q11+O12*Q12+O13*Q13+O15*Q15+O16*Q16+O18*Q18+O19*Q19+O20*Q20+O21*Q21+O22*Q22+O23*Q23+O24*Q24+O25*Q25+O27*Q27+O28*Q28+O29*Q29+O31*Q31+O32*Q32+O34*Q34+O35*Q35+O37*Q37 -> 532.49089 | R40: =O4*R4+O5*R5+O6*R6+O7*R7+O9*R9+O10*R10+O11*R11+O12*R12+O13*R13+O15*R15+O16*R16+O18*R18+O19*R19+O20*R20+O21*R21+O22*R22+O23*R23+O24*R24+O25*R25+O27*R27+O28*R28+O29*R29+O31*R31+O32*R32+O34*R34+O35*R35+O37*R37 -> 1278.8409 | S40: =O4*S4+O5*S5+O6*S6+O7*S7+O9*S9+O10*S10+O11*S11+O12*S12+O13*S13+O15*S15+O16*S16+O18*S18+O19*S19+O20*S20+O21*S21+O22*S22+O23*S23+O24*S24+O25*S25+O27*S27+O28*S28+O29*S29+O31*S31+O32*S32+O34*S34+O35*S35+O37*S37 -> 1330.7009 | T40: =O4*T4+O5*T5+O6*T6+O7*T7+O9*T9+O10*T10+O11*T11+O12*T12+O13*T13+O15*T15+O16*T16+O18*T18+O19*T19+O20*T20+O21*T21+O22*T22+O23*T23+O24*T24+O25*T25+O27*T27+O28*T28+O29*T29+O31*T31+O32*T32+O34*T34+O35*T35+O37*T37 -> 2876.7009 | U40: =O4*U4+O5*U5+O6*U6+O7*U7+O9*U9+O10*U10+O11*U11+O12*U12+O13*U13+O15*U15+O16*U16+O18*U18+O19*U19+O20*U20+O21*U21+O22*U22+O23*U23+O24*U24+O25*U25+O27*U27+O28*U28+O29*U29+O31*U31+O32*U32+O34*U34+O35*U35+O37*U37 -> 1243.2009 | V40: =O4*V4+O5*V5+O6*V6+O7*V7+O9*V9+O10*V10+O11*V11+O12*V12+O13*V13+O15*V15+O16*V16+O18*V18+O19*V19+O20*V20+O21*V21+O22*V22+O23*V23+O24*V24+O25*V25+O27*V27+O28*V28+O29*V29+O31*V31+O32*V32+O34*V34+O35*V35+O37*V37 -> 532.60089 | W40: =O4*W4+O5*W5+O6*W6+O7*W7+O9*W9+O10*W10+O11*W11+O12*W12+O13*W13+O15*W15+O16*W16+O18*W18+O19*W19+O20*W20+O21*W21+O22*W22+O23*W23+O24*W24+O25*W25+O27*W27+O28*W28+O29*W29+O31*W31+O32*W32+O34*W34+O35*W35+O37*W37 -> 1163.8577 | X40: =O4*X4+O5*X5+O6*X6+O7*X7+O9*X9+O10*X10+O11*X11+O12*X12+O13*X13+O15*X15+O16*X16+O18*X18+O19*X19+O20*X20+O21*X21+O22*X22+O23*X23+O24*X24+O25*X25+O27*X27+O28*X28+O29*X29+O31*X31+O32*X32+O34*X34+O35*X35+O37*X37 -> 477.83089 | Y40: MEV × mode flag. Reflects contingency per component.
...
